2019-09-14 19:37:36,904 - ERROR - ConnectionError occurred, args=(MaxRetryError("HTTPSConnectionPool(host='api.telegram.org', port=443): Max retries exceeded with url: /bot957097853:AAH3adXTzvNPNNsQ0vDJ4IoQVJc4-MSz3xM/getUpdates?timeout=20&offset=1 (Caused by ProxyError('Cannot connect to proxy.', OSError(101, 'Network is unreachable')))",),)
Traceback (most recent call last):
  File "/home/user-sau-nuc/Repos/ip_telegram_bot/virtualenv/env/lib/python3.5/site-packages/requests/packages/urllib3/connectionpool.py", line 539, in urlopen
    self._prepare_proxy(conn)
  File "/home/user-sau-nuc/Repos/ip_telegram_bot/virtualenv/env/lib/python3.5/site-packages/requests/packages/urllib3/connectionpool.py", line 727, in _prepare_proxy
    conn.connect()
  File "/home/user-sau-nuc/Repos/ip_telegram_bot/virtualenv/env/lib/python3.5/site-packages/requests/packages/urllib3/connection.py", line 204, in connect
    conn = self._new_conn()
  File "/home/user-sau-nuc/Repos/ip_telegram_bot/virtualenv/env/lib/python3.5/site-packages/requests/packages/urllib3/connection.py", line 134, in _new_conn
    (self.host, self.port), self.timeout, **extra_kw)
  File "/home/user-sau-nuc/Repos/ip_telegram_bot/virtualenv/env/lib/python3.5/site-packages/requests/packages/urllib3/util/connection.py", line 88, in create_connection
    raise err
  File "/home/user-sau-nuc/Repos/ip_telegram_bot/virtualenv/env/lib/python3.5/site-packages/requests/packages/urllib3/util/connection.py", line 78, in create_connection
    sock.connect(sa)
OSError: [Errno 101] Network is unreachable

During handling of the above exception, another exception occurred:

Traceback (most recent call last):
  File "/home/user-sau-nuc/Repos/ip_telegram_bot/virtualenv/env/lib/python3.5/site-packages/requests/adapters.py", line 370, in send
    timeout=timeout
  File "/home/user-sau-nuc/Repos/ip_telegram_bot/virtualenv/env/lib/python3.5/site-packages/requests/packages/urllib3/connectionpool.py", line 597, in urlopen
    _stacktrace=sys.exc_info()[2])
  File "/home/user-sau-nuc/Repos/ip_telegram_bot/virtualenv/env/lib/python3.5/site-packages/requests/packages/urllib3/util/retry.py", line 271, in increment
    raise MaxRetryError(_pool, url, error or ResponseError(cause))
requests.packages.urllib3.exceptions.MaxRetryError: HTTPSConnectionPool(host='api.telegram.org', port=443): Max retries exceeded with url: /bot957097853:AAH3adXTzvNPNNsQ0vDJ4IoQVJc4-MSz3xM/getUpdates?timeout=20&offset=1 (Caused by ProxyError('Cannot connect to proxy.', OSError(101, 'Network is unreachable')))

During handling of the above exception, another exception occurred:

Traceback (most recent call last):
  File "/home/user-sau-nuc/Repos/ip_telegram_bot/virtualenv/env/lib/python3.5/site-packages/telebot/util.py", line 59, in run
    task(*args, **kwargs)
  File "/home/user-sau-nuc/Repos/ip_telegram_bot/virtualenv/env/lib/python3.5/site-packages/telebot/__init__.py", line 276, in __retrieve_updates
    updates = self.get_updates(offset=(self.last_update_id + 1), timeout=timeout)
  File "/home/user-sau-nuc/Repos/ip_telegram_bot/virtualenv/env/lib/python3.5/site-packages/telebot/__init__.py", line 246, in get_updates
    json_updates = apihelper.get_updates(self.token, offset, limit, timeout, allowed_updates)
  File "/home/user-sau-nuc/Repos/ip_telegram_bot/virtualenv/env/lib/python3.5/site-packages/telebot/apihelper.py", line 180, in get_updates
    return _make_request(token, method_url, params=payload)
  File "/home/user-sau-nuc/Repos/ip_telegram_bot/virtualenv/env/lib/python3.5/site-packages/telebot/apihelper.py", line 54, in _make_request
    timeout=(connect_timeout, read_timeout), proxies=proxy)
  File "/home/user-sau-nuc/Repos/ip_telegram_bot/virtualenv/env/lib/python3.5/site-packages/requests/sessions.py", line 465, in request
    resp = self.send(prep, **send_kwargs)
  File "/home/user-sau-nuc/Repos/ip_telegram_bot/virtualenv/env/lib/python3.5/site-packages/requests/sessions.py", line 573, in send
    r = adapter.send(request, **kwargs)
  File "/home/user-sau-nuc/Repos/ip_telegram_bot/virtualenv/env/lib/python3.5/site-packages/requests/adapters.py", line 424, in send
    raise ConnectionError(e, request=request)
requests.exceptions.ConnectionError: HTTPSConnectionPool(host='api.telegram.org', port=443): Max retries exceeded with url: /bot957097853:AAH3adXTzvNPNNsQ0vDJ4IoQVJc4-MSz3xM/getUpdates?timeout=20&offset=1 (Caused by ProxyError('Cannot connect to proxy.', OSError(101, 'Network is unreachable')))

2019-09-14 19:37:36,909 - ERROR - HTTPSConnectionPool(host='api.telegram.org', port=443): Max retries exceeded with url: /bot957097853:AAH3adXTzvNPNNsQ0vDJ4IoQVJc4-MSz3xM/getUpdates?timeout=20&offset=1 (Caused by ProxyError('Cannot connect to proxy.', OSError(101, 'Network is unreachable')))
Traceback (most recent call last):
  File "/home/user-sau-nuc/Repos/ip_telegram_bot/virtualenv/env/lib/python3.5/site-packages/requests/packages/urllib3/connectionpool.py", line 539, in urlopen
    self._prepare_proxy(conn)
  File "/home/user-sau-nuc/Repos/ip_telegram_bot/virtualenv/env/lib/python3.5/site-packages/requests/packages/urllib3/connectionpool.py", line 727, in _prepare_proxy
    conn.connect()
  File "/home/user-sau-nuc/Repos/ip_telegram_bot/virtualenv/env/lib/python3.5/site-packages/requests/packages/urllib3/connection.py", line 204, in connect
    conn = self._new_conn()
  File "/home/user-sau-nuc/Repos/ip_telegram_bot/virtualenv/env/lib/python3.5/site-packages/requests/packages/urllib3/connection.py", line 134, in _new_conn
    (self.host, self.port), self.timeout, **extra_kw)
  File "/home/user-sau-nuc/Repos/ip_telegram_bot/virtualenv/env/lib/python3.5/site-packages/requests/packages/urllib3/util/connection.py", line 88, in create_connection
    raise err
  File "/home/user-sau-nuc/Repos/ip_telegram_bot/virtualenv/env/lib/python3.5/site-packages/requests/packages/urllib3/util/connection.py", line 78, in create_connection
    sock.connect(sa)
OSError: [Errno 101] Network is unreachable

During handling of the above exception, another exception occurred:

Traceback (most recent call last):
  File "/home/user-sau-nuc/Repos/ip_telegram_bot/virtualenv/env/lib/python3.5/site-packages/requests/adapters.py", line 370, in send
    timeout=timeout
  File "/home/user-sau-nuc/Repos/ip_telegram_bot/virtualenv/env/lib/python3.5/site-packages/requests/packages/urllib3/connectionpool.py", line 597, in urlopen
    _stacktrace=sys.exc_info()[2])
  File "/home/user-sau-nuc/Repos/ip_telegram_bot/virtualenv/env/lib/python3.5/site-packages/requests/packages/urllib3/util/retry.py", line 271, in increment
    raise MaxRetryError(_pool, url, error or ResponseError(cause))
requests.packages.urllib3.exceptions.MaxRetryError: HTTPSConnectionPool(host='api.telegram.org', port=443): Max retries exceeded with url: /bot957097853:AAH3adXTzvNPNNsQ0vDJ4IoQVJc4-MSz3xM/getUpdates?timeout=20&offset=1 (Caused by ProxyError('Cannot connect to proxy.', OSError(101, 'Network is unreachable')))

During handling of the above exception, another exception occurred:

Traceback (most recent call last):
  File "bot.py", line 64, in <module>
    bot.polling(none_stop=True, interval=1)
  File "/home/user-sau-nuc/Repos/ip_telegram_bot/virtualenv/env/lib/python3.5/site-packages/telebot/__init__.py", line 389, in polling
    self.__threaded_polling(none_stop, interval, timeout)
  File "/home/user-sau-nuc/Repos/ip_telegram_bot/virtualenv/env/lib/python3.5/site-packages/telebot/__init__.py", line 412, in __threaded_polling
    polling_thread.raise_exceptions()
  File "/home/user-sau-nuc/Repos/ip_telegram_bot/virtualenv/env/lib/python3.5/site-packages/telebot/util.py", line 78, in raise_exceptions
    six.reraise(self.exc_info[0], self.exc_info[1], self.exc_info[2])
  File "/home/user-sau-nuc/Repos/ip_telegram_bot/virtualenv/env/lib/python3.5/site-packages/six.py", line 686, in reraise
    raise value
  File "/home/user-sau-nuc/Repos/ip_telegram_bot/virtualenv/env/lib/python3.5/site-packages/telebot/util.py", line 59, in run
    task(*args, **kwargs)
  File "/home/user-sau-nuc/Repos/ip_telegram_bot/virtualenv/env/lib/python3.5/site-packages/telebot/__init__.py", line 276, in __retrieve_updates
    updates = self.get_updates(offset=(self.last_update_id + 1), timeout=timeout)
  File "/home/user-sau-nuc/Repos/ip_telegram_bot/virtualenv/env/lib/python3.5/site-packages/telebot/__init__.py", line 246, in get_updates
    json_updates = apihelper.get_updates(self.token, offset, limit, timeout, allowed_updates)
  File "/home/user-sau-nuc/Repos/ip_telegram_bot/virtualenv/env/lib/python3.5/site-packages/telebot/apihelper.py", line 180, in get_updates
    return _make_request(token, method_url, params=payload)
  File "/home/user-sau-nuc/Repos/ip_telegram_bot/virtualenv/env/lib/python3.5/site-packages/telebot/apihelper.py", line 54, in _make_request
    timeout=(connect_timeout, read_timeout), proxies=proxy)
  File "/home/user-sau-nuc/Repos/ip_telegram_bot/virtualenv/env/lib/python3.5/site-packages/requests/sessions.py", line 465, in request
    resp = self.send(prep, **send_kwargs)
  File "/home/user-sau-nuc/Repos/ip_telegram_bot/virtualenv/env/lib/python3.5/site-packages/requests/sessions.py", line 573, in send
    r = adapter.send(request, **kwargs)
  File "/home/user-sau-nuc/Repos/ip_telegram_bot/virtualenv/env/lib/python3.5/site-packages/requests/adapters.py", line 424, in send
    raise ConnectionError(e, request=request)
requests.exceptions.ConnectionError: HTTPSConnectionPool(host='api.telegram.org', port=443): Max retries exceeded with url: /bot957097853:AAH3adXTzvNPNNsQ0vDJ4IoQVJc4-MSz3xM/getUpdates?timeout=20&offset=1 (Caused by ProxyError('Cannot connect to proxy.', OSError(101, 'Network is unreachable')))
